<?xml version="1.0" ?>
<!-- =================================================================================== -->
<!-- |    This document was autogenerated by xacro from ./irac_noGazebo.xacro          | -->
<!-- |    EDITING THIS FILE BY HAND IS NOT RECOMMENDED                                 | -->
<!-- =================================================================================== -->
<!-- Revolute-Revolute Manipulator -->
<robot name="irac" xmlns:xacro="http://www.ros.org/wiki/xacro">
  <material name="black">
    <color rgba="0.0 0.0 0.0 1.0"/>
  </material>
  <material name="blue">
    <color rgba="0.0 0.0 0.8 1.0"/>
  </material>
  <material name="green">
    <color rgba="0.0 0.8 0.0 1.0"/>
  </material>
  <material name="grey">
    <color rgba="0.2 0.2 0.2 1.0"/>
  </material>
  <material name="orange">
    <color rgba="1.0 0.423529411765 0.0392156862745 1.0"/>
  </material>
  <material name="brown">
    <color rgba="0.870588235294 0.811764705882 0.764705882353 1.0"/>
  </material>
  <material name="red">
    <color rgba="0.8 0.0 0.0 1.0"/>
  </material>
  <material name="white">
    <color rgba="1.0 1.0 1.0 1.0"/>
  </material>
  <!-- Used for fixing robot to Gazebo 'base_link' -->
  <link name="world"/>
  <!-- Link 1 || BASE -->
  <link name="link1">
    <collision>
      <origin rpy="0 0 0" xyz="0 0 0"/>
      <geometry>
        <mesh filename="/home/kurt/Senior_Design/src/IRAC/urdf/meshes/Base.stl" scale=".001 .001 .001"/>
      </geometry>
    </collision>
    <visual>
      <origin rpy="0 0 0" xyz="0 0 0"/>
      <geometry>
        <mesh filename="/home/kurt/Senior_Design/src/IRAC/urdf/meshes/Base.stl" scale=".001 .001 .001"/>
      </geometry>
      <material name="orange"/>
    </visual>
    <inertial>
      <origin rpy="0 0 0" xyz="0 0 0"/>
      <mass value="0.4"/>
      <inertia ixx="0.000770536333333" ixy="0.0" ixz="0.0" iyy="0.000770536333333" iyz="0.0" izz="0.00024"/>
    </inertial>
  </link>
  <!-- JOINT 1 -->
  <joint name="joint1" type="continuous">
    <parent link="world"/>
    <child link="link1"/>
    <origin rpy="0 0 0" xyz="0 0 0"/>
    <axis xyz="0 0 1"/>
    <dynamics damping="0.7"/>
    <!-- <limit lower="${-PI/2}" upper="${PI/2}" effort="30.0" velocity="10.0"/> -->
  </joint>
  <!-- Link 2 -->
  <link name="link2">
    <collision>
      <origin rpy="0 0 0" xyz="0 0 0"/>
      <geometry>
        <mesh filename="/home/kurt/Senior_Design/src/IRAC/urdf/meshes/Link1.stl" scale=".001 .001 .001"/>
      </geometry>
    </collision>
    <visual>
      <origin rpy="0 0 0" xyz="0 0 0"/>
      <geometry>
        <mesh filename="/home/kurt/Senior_Design/src/IRAC/urdf/meshes/Link1.stl" scale=".001 .001 .001"/>
      </geometry>
      <material name="blue"/>
    </visual>
    <inertial>
      <origin rpy="0 0 0" xyz="0 0 0"/>
      <mass value="0.4"/>
      <inertia ixx="0.00363563525333" ixy="0.0" ixz="0.0" iyy="0.00363563525333" iyz="0.0" izz="0.00024"/>
    </inertial>
  </link>
  <!-- JOINT 2 -->
  <joint name="joint2" type="continuous">
    <parent link="link1"/>
    <child link="link2"/>
    <origin rpy="0 0 0" xyz="0 -0.0301625 .127175"/>
    <axis xyz="0 1 0"/>
    <dynamics damping="0.7"/>
    <!-- <limit lower="${-PI/2}" upper="${PI/2}" effort="30.0" velocity="10.0"/> -->
  </joint>
  <!-- Link 3 -->
  <link name="link3">
    <collision>
      <origin rpy="0 0 0" xyz="0 0 0"/>
      <geometry>
        <mesh filename="/home/kurt/Senior_Design/src/IRAC/urdf/meshes/Link2.stl" scale=".001 .001 .001"/>
      </geometry>
    </collision>
    <visual>
      <origin rpy="0 0 0" xyz="0 0 0"/>
      <geometry>
        <mesh filename="/home/kurt/Senior_Design/src/IRAC/urdf/meshes/Link2.stl" scale=".001 .001 .001"/>
      </geometry>
      <material name="orange"/>
    </visual>
    <inertial>
      <origin rpy="0 0 0" xyz="0 0 0"/>
      <mass value="0.4"/>
      <inertia ixx="0.00281156352" ixy="0.0" ixz="0.0" iyy="0.00281156352" iyz="0.0" izz="0.00024"/>
    </inertial>
  </link>
  <!-- JOINT 3 -->
  <joint name="joint3" type="continuous">
    <parent link="link2"/>
    <child link="link3"/>
    <origin rpy="0 0 0" xyz="0 0 .28076"/>
    <axis xyz="0 1 0"/>
    <dynamics damping="0.7"/>
    <!-- <limit lower="${-PI/2}" upper="${PI/2}" effort="30.0" velocity="10.0"/> -->
  </joint>
  <!-- LINK 4-->
  <link name="link4">
    <collision>
      <origin rpy="0 0 0" xyz="0 0 0"/>
      <geometry>
        <mesh filename="/home/kurt/Senior_Design/src/IRAC/urdf/meshes/Link3.stl" scale=".001 .001 .001"/>
      </geometry>
    </collision>
    <visual>
      <origin rpy="0 0 0" xyz="0 0 0"/>
      <geometry>
        <mesh filename="/home/kurt/Senior_Design/src/IRAC/urdf/meshes/Link3.stl" scale=".001 .001 .001"/>
      </geometry>
      <material name="orange"/>
    </visual>
    <inertial>
      <origin rpy="0 0 0" xyz="0 0 0"/>
      <mass value="0.4"/>
      <inertia ixx="0.000605214083333" ixy="0.0" ixz="0.0" iyy="0.000605214083333" iyz="0.0" izz="0.00024"/>
    </inertial>
  </link>
  <!-- JOINT 4 -->
  <joint name="joint4" type="continuous">
    <parent link="link3"/>
    <child link="link4"/>
    <origin rpy="0 0 0" xyz="0 .05237 .25975"/>
    <axis xyz="0 1 0"/>
    <dynamics damping="0.7"/>
    <!-- <limit lower="${-PI/2}" upper="${PI/2}" effort="30.0" velocity="10.0"/> -->
  </joint>
  <link name="flange"/>
  <joint name="flange" type="fixed">
    <origin rpy="0.0 0.0 0.0" xyz=" 0.0 0.0 0.1206"/>
    <parent link="link4"/>
    <child link="flange"/>
  </joint>
</robot>
